Workbook

Sheet Pivot
A1: adapter_code | B1: TSGTATPCLOUDDB_CONN
A2: TSGTAtpCloudDB_Conn
A3: Integration Names / Invoke | B3: Description
A4: TSGTCmnARErpOrchestratorIbFwk_Service | B4: =VLOOKUP(A4,IntegrationsNames!B1:D199,3,FALSE) -> This integration will call procedure to generate FBDI to Obj storage; get FBDI from Obj storage and call ERP Integration Service
A5: TSGTCmnErpDataSyncDispatcherObFwk_Service | B5: =VLOOKUP(A5,IntegrationsNames!B2:D200,3,FALSE) -> Picks up the file from Object Storage and insert into FND_OB_STG table.
A6: TSGTCmnErpDispatcherDataInsertObFwk_Service | B6: =VLOOKUP(A6,IntegrationsNames!B3:D201,3,FALSE) -> Data insert service to OB_STG table
A7: TSGTCmnErpMediatorDataInsertIbFwk_Service | B7: =VLOOKUP(A7,IntegrationsNames!B4:D202,3,FALSE) -> Inbound Framework Service: Read and insert to the stage table; This service will called from the Inbound Mediator service. process : Download from SFTP. Read the file. Enrich the file ;Insert to DB table and send the response.
A8: TSGTCmnErpMediatorIbFwk_Service | B8: =VLOOKUP(A8,IntegrationsNames!B5:D203,3,FALSE) -> This Mediator Service validates and enrich the input file; prepares the FBDI format data and sends the data to Orchestrator Service
A9: TSGTInvErpOnHandDataSyncDispatcherObFwk_Service | B9: =VLOOKUP(A9,IntegrationsNames!B6:D204,3,FALSE) -> Picks up the file from Object Storage and insert into FND_OB_STG table.
A10: TSGTInvOnHandReconOrchestratorIbFwk_Service | B10: =VLOOKUP(A10,IntegrationsNames!B7:D205,3,FALSE) -> This integration will call procedure to compare Erp and WACS OnHand Item Quantities and generate the reconciliation report
A11: TSGTInvWacsOnHandMediatorDataInsertIbFwk_Service | B11: =VLOOKUP(A11,IntegrationsNames!B8:D206,3,FALSE) -> Inventory OnHand Service: Read and insert to the stage table; This service will called from the Inbound Mediator service. process : Download from SFTP. Read the file. Insert to DB table and send the response.
A12: TSGTMingenCheckRunStatus_Service | B12: =VLOOKUP(A12,IntegrationsNames!B9:D207,3,FALSE) -> Integration Identifier: INTE109;** This Interface checks the status of Mingen Report. If Mingen Report is completed; then this interface returns the Success Status along with the Report Sftp Server Path and the Object Storage link as well.
A13: TSGTMingenErpIbInit_Service | B13: =VLOOKUP(A13,IntegrationsNames!B10:D208,3,FALSE) -> Integration Identifier: INTE109;** Integration will trigger the TSGTCmnLauncherFwk_Service to generate the Mingen Report and send the report as attachment in the email and also post it to sftp.
A14: TSGTMingenErpIbReport_Service | B14: =VLOOKUP(A14,IntegrationsNames!B11:D209,3,FALSE) -> Integration Identifier: INTE109;** Integration will generate the Mingen Report and Based on Delivery Mode sends the report as attachment in the email; post it to SFTP; Stores in Object Storage.
A15: TSGTMingenErpLockControl_Service | B15: =VLOOKUP(A15,IntegrationsNames!B12:D210,3,FALSE) -> This integration controls the lock in the TSGT_MINGEN_LOCK_TBL
... A19: Grand Total | B19: =VLOOKUP(A19,IntegrationsNames!B16:D214,3,FALSE) -> #N/A
B20: =VLOOKUP(A20,IntegrationsNames!B17:D215,3,FALSE) -> #N/A
B21: =VLOOKUP(A21,IntegrationsNames!B18:D216,3,FALSE) -> #N/A
B22: =VLOOKUP(A22,IntegrationsNames!B19:D217,3,FALSE) -> #N/A
B23: =VLOOKUP(A23,IntegrationsNames!B20:D218,3,FALSE) -> #N/A
B24: =VLOOKUP(A24,IntegrationsNames!B21:D219,3,FALSE) -> #N/A
B25: =VLOOKUP(A25,IntegrationsNames!B22:D220,3,FALSE) -> #N/A
B26: =VLOOKUP(A26,IntegrationsNames!B23:D221,3,FALSE) -> #N/A
B27: =VLOOKUP(A27,IntegrationsNames!B24:D222,3,FALSE) -> #N/A
B28: =VLOOKUP(A28,IntegrationsNames!B25:D223,3,FALSE) -> #N/A
B29: =VLOOKUP(A29,IntegrationsNames!B26:D224,3,FALSE) -> #N/A
B30: =VLOOKUP(A30,IntegrationsNames!B27:D225,3,FALSE) -> #N/A
B31: =VLOOKUP(A31,IntegrationsNames!B28:D226,3,FALSE) -> #N/A
... B60: =VLOOKUP(A60,IntegrationsNames!B57:D255,3,FALSE) -> #N/A

Sheet IntegrationsNames
A1: id | B1: name | C1: version | D1: description
A2: FA_TAX_EPM_FTP|01.00.0001 | B2: FA_TAX_EPM_Monthly_TAX_LOAD | C2: 01.00.0001 | D2: https://www.oracle.com/pls/topic/lookup?ctx=en/cloud/paas/integration-cloud&id=INTRA-GUID-721BB0DB-5073-4560-8128-3881B460B4EC
A3: FA_TAX_EPM_LOC_CAT_LOAD|01.00.0001 | B3: FA_TAX_EPM_LOC-CAT_LOAD | C3: 01.00.0001 | D3: https://www.oracle.com/pls/topic/lookup?ctx=en/cloud/paas/integration-cloud&id=INTRA-GUID-721BB0DB-5073-4560-8128-3881B460B4EC
A4: FTP_HCM_EPM_FILE_UPLOA_PROJE|01.00.0001 | B4: FTP HCM EPM File Upload_Projects | C4: 01.00.0001 | D4: https://www.oracle.com/pls/topic/lookup?ctx=en/cloud/paas/integration-cloud&id=INTRA-GUID-721BB0DB-5073-4560-8128-3881B460B4EC
A5: FTP_HCM_EPM_FILE_UPLOAD|01.00.0001 | B5: FTP HCM EPM File Upload | C5: 01.00.0001 | D5: https://www.oracle.com/pls/topic/lookup?ctx=en/cloud/paas/integration-cloud&id=INTRA-GUID-721BB0DB-5073-4560-8128-3881B460B4EC
A6: FTP_PPM_EPM_FILE_UPLOAD|01.00.0001 | B6: FTP PPM EPM File Upload | C6: 01.00.0001 | D6: https://www.oracle.com/pls/topic/lookup?ctx=en/cloud/paas/integration-cloud&id=INTRA-GUID-721BB0DB-5073-4560-8128-3881B460B4EC
A7: OUTL-BA-FPRC_WACS_BC_SYNC|01.22.3000 | B7: Oracle Utilities FPRC WACS Blanket Contracts Sync | C7: 01.22.3000 | D7: Syncs Blanket Contracts from Oracle Procurement Cloud(FPRC) to Work and Asset Cloud Service (WACS). This integration is used for both initial load and incremental update sync of Blanket Contract Information.
A8: OUTL-BA-FPRC_WACS_VEND_LOC_SYNC|01.22.3000 | B8: Oracle Utilities FPRC WACS Vendor Locations Sync | C8: 01.22.3000 | D8: Integration flow to sync Vendor Locations from Oracle Procurement Cloud to WACS
A9: OUTL-BA-OFSC_WACS_ACTIVITY_STAT|01.22.3000 | B9: Oracle Utilities OFSC WACS Activity Interim Status | C9: 01.22.3000 | D9: Sends Activity status from OFSC to WAM.
A10: OUTL-BA-OFSC_WACS_ASSET_QUERY|01.22.3000 | B10: Oracle Utilities OFSC WACS Asset Query | C10: 01.22.3000 | D10: This integration flow queries the asset information from WACS.
A11: OUTL-BA-OFSC_WACS_STOREROOM_SYNC|01.22.3000 | B11: Oracle Utilities OFSC WACS Storeroom Sync | C11: 01.22.3000 | D11: This integration flow syncs/update truck storeroom inventory data from WAM to OFSC
A12: OUTL-BA-OFSC_WACS_WORK_REQ|01.22.3000 | B12: Oracle Utilities OFSC WACS Work Request | C12: 01.22.3000 | D12: This flow creates the Work request from OFSC to WACS
... A67: TSGTAUDITINGPROC_SERVICE|01.02.0002 | B67: TSGTAuditingProcess_Service | C67: 01.02.0002 | D67: V1.2.2 - Global Catch log execute message;V1.2.1 - default Body values if not present;V1.2.0 - Added OIC Service Instance in email message
A68: TSGTAZUREADEMPLOYEESOUTBOUNDHCM|02.03.0000 | B68: TSGTAzureADEmployeesOutboundHCM | C68: 02.03.0000
A69: TSGTCMNAPPCOMPOS_SERVICE|01.00.0000 | B69: TSGTCmnAppComposerObjUpdate_Service | C69: 01.00.0000
A70: TSGTCMNARERPORCH_SERVICE|01.00.0000 | B70: TSGTCmnARErpOrchestratorIbFwk_Service | C70: 01.00.0000 | D70: This integration will call procedure to generate FBDI to Obj storage; get FBDI from Obj storage and call ERP Integration Service
A71: TSGTCMNCHECKESSJOBSTATUS_SERVICE|01.00.0000 | B71: TSGTCmnCheckESSJOBStatus_Service | C71: 01.00.0000 | D71: Utility Service: This Integration Service will get the ESS Process Id and Invoke the SOAP Service to receive the ESS Job Status [SUCCESS/ERROR/TIMEOUT].
A72: TSGTCMNERPCALLBA_SERVICE|01.00.0000 | B72: TSGTCmnErpCallbackObFwk_Service | C72: 01.00.0000 | D72: Common framework to receive callback for Outbound ESS Jobs from Oracle fusion application
A73: TSGTCMNERPCALLBACKIBFWK_SERVICE|01.00.0000 | B73: TSGTCmnErpCallbackIbFwk_Service | C73: 01.00.0000 | D73: Common Inbound framework to receive callback from Oracle fusion application
A74: TSGTCMNERPDATASY_SERVICE|01.00.0000 | B74: TSGTCmnErpDataSyncDispatcherObFwk_Service | C74: 01.00.0000 | D74: Picks up the file from Object Storage and insert into FND_OB_STG table.
A75: TSGTCMNERPDISPAT_SERVICE|01.00.0000 | B75: TSGTCmnErpDispatcherDataInsertObFwk_Service | C75: 01.00.0000 | D75: Data insert service to OB_STG table
A76: TSGTCMNERPLAUNCH_SERVICE_OB|01.00.0000 | B76: TSGTCmnErpLauncherObFwk_Service | C76: 01.00.0000 | D76: Common Framework Outbound Integration will Submit Custom ESS Job in SaaS which will upload the Output Extract to UCM.
A77: TSGTCMNERPLAUNCH_SERVICE|01.00.0000 | B77: TSGTCmnErpLauncherIbFwk_Service | C77: 01.00.0000 | D77: Common Launcher to trigger ERP Integrations
A78: TSGTCMNERPMEDIATDATAINSER_SERVIC|01.00.0000 | B78: TSGTCmnErpMediatorDataInsertIbFwk_Service | C78: 01.00.0000 | D78: Inbound Framework Service: Read and insert to the stage table; This service will called from the Inbound Mediator service. process : Download from SFTP. Read the file. Enrich the file ;Insert to DB table and send the response.
A79: TSGTCMNERPMEDIATORIBFWK_SERVICE|01.00.0000 | B79: TSGTCmnErpMediatorIbFwk_Service | C79: 01.00.0000 | D79: This Mediator Service validates and enrich the input file; prepares the FBDI format data and sends the data to Orchestrator Service
A80: TSGTCMNERPSFTPDISPOBFWK_SERVICE|01.00.0000 | B80: TSGTCmnErpSftpDispatcherObFwk_Service | C80: 01.00.0000 | D80: Common framework to transfer file from Object Storage to SFTP for Outbound Integration
A81: TSGTCMNFILEREFER_SERVICE|01.00.0000 | B81: TSGTCmnFileReferencetoObjectStorage_Service | C81: 01.00.0000 | D81: This Interface moves the file reference (Base64 encoded from) to the object storage.
... A83: TSGTCMNGETESSLOGOUT_SERVICE|01.00.0000 | B83: TSGTCmnGetEssLogOutput_Service | C83: 01.00.0000 | D83: This Integration extracts the Log and Output Files of an ESS Job
A84: TSGTCMNHCMDISPAT_SERVICE|01.00.0000 | B84: TSGTCmnHcmDispatcher_Service | C84: 01.00.0000
A85: TSGTCMNHCMDISPAT_SERVICE|02.00.0001 | B85: TSGTCmnHcmDispatcher_Service | C85: 02.00.0001 | D85: V2.0 - Remove encryption for SailPoint;V1.2 - SailPoint route only SailPoint target system;- COBRA added ;V1.0.0 servers VSP; EPM; SNAP; HSA; Kaiser; DeltaDental
A86: TSGTCMNHCMEXTRAC_SERVICE|01.00.0000 | B86: TSGTCmnHcmExtractProcess_Service | C86: 01.00.0000
A87: TSGTCMNHCMINBOUN_SERVICE|01.00.0000 | B87: TSGTCmnHcmInboundProcess_Service | C87: 01.00.0000
A88: TSGTCMNHCMLAUNCH_SERVICE|01.00.0000 | B88: TSGTCmnHcmLauncherFwk_Service | C88: 01.00.0000
A89: TSGTCMNHCMNOTIFI_SERVICE|01.00.0000 | B89: TSGTCmnHcmNotification_Service | C89: 01.00.0000
A90: TSGTCMNLAUNCHERF_SERVICE|01.00.0000 | B90: TSGTCmnLauncherFwk_Service | C90: 01.00.0000 | D90: Integration that is kicked-off from the Adhoc submission UI screen
A91: TSGTCMNNOTIFICAT_SERVICE|01.00.0000 | B91: TSGTCmnNotificationFwk_Service | C91: 01.00.0000 | D91: Generic notification service call from the Inbound and outbound integrations
A92: TSGTCMNOBJECTSTOSFTPMOVE_SERVICE|01.00.0000 | B92: TSGTCmnObjectStorageToSFTPMove_Service | C92: 01.00.0000 | D92: This Interface moves the file from object storage to the different sftp path.
A93: TSGTCMNOBJSTRGFI_SERVICE|01.00.0000 | B93: TSGTCmnObjStrgFileDownload_Service | C93: 01.00.0000 | D93: Integration to download files from Object storage buckets
A94: TSGTCMNOBJSTRGFILE_SERVICE|01.00.0000 | B94: TSGTCmnObjStrgFile_Service | C94: 01.00.0000 | D94: Find/Delete file in object storage
A95: TSGTCMNOBJSTRGPU_SERVICE|01.00.0000 | B95: TSGTCmnObjStrgPurge_Service | C95: 01.00.0000 | D95: To Purge the Object Storage Files
...

Sheet INVOKE-XREF
A1: source_file | B1: source_integration | C1: source_integration_code | D1: source_integration_name | E1: source_integration_version | F1: invoke | G1: call_type | H1: target_integration_code | I1: target_version | J1: target_integration_name | K1: resource_uri | L1: adapter_code | M1: application_name | N1: error
A2: BIP_SCHEDU_REPORT_WSS_SERVIC_01.00.0000.iar.yaml | B2: BIP_SCHEDU_REPORT_WSS_SERVIC 01.00.0000 | C2: BIP_SCHEDU_REPORT_WSS_SERVIC | D2: BIP Schedule Report WSS Service | E2: 01.00.0000 | F2: SubmitScheduleReport(i0) | G2: Adapter_Invoke | L2: BIP_SCHEDULEREPORTWS | M2: SubmitScheduleReport
A3: FA_TAX_EPM_FTP_01.00.0001.iar.yaml | B3: FA_TAX_EPM_FTP 01.00.0001 | C3: FA_TAX_EPM_FTP | D3: FA_TAX_EPM_Monthly_TAX_LOAD | E3: 01.00.0001 | F3: ftp_location(i0) | G3: Adapter_Invoke | L3: ORCL-BRT-FTP_CONN | M3: ftp_location
A4: FA_TAX_EPM_FTP_01.00.0001.iar.yaml | B4: FA_TAX_EPM_FTP 01.00.0001 | C4: FA_TAX_EPM_FTP | D4: FA_TAX_EPM_Monthly_TAX_LOAD | E4: 01.00.0001 | F4: FA_TAX_EPMrestupload(i2) | G4: Adapter_Invoke | K4: /interop/rest/11.1.2.3.600/applicationsnapshots/{file_name}/contents | L4: ORACL_REST_EPM_CONNE_FA_TAX | M4: FA_TAX_EPMrestupload
A5: FA_TAX_EPM_LOC_CAT_LOAD_01.00.0001.iar.yaml | B5: FA_TAX_EPM_LOC_CAT_LOAD 01.00.0001 | C5: FA_TAX_EPM_LOC_CAT_LOAD | D5: FA_TAX_EPM_LOC-CAT_LOAD | E5: 01.00.0001 | F5: ftp_location(i0) | G5: Adapter_Invoke | L5: ORCL-BRT-FTP_CONN | M5: ftp_location
A6: FA_TAX_EPM_LOC_CAT_LOAD_01.00.0001.iar.yaml | B6: FA_TAX_EPM_LOC_CAT_LOAD 01.00.0001 | C6: FA_TAX_EPM_LOC_CAT_LOAD | D6: FA_TAX_EPM_LOC-CAT_LOAD | E6: 01.00.0001 | F6: FA_TAX_EPMrestupload(i2) | G6: Adapter_Invoke | K6: /interop/rest/11.1.2.3.600/applicationsnapshots/{file_name}/contents | L6: ORACL_REST_EPM_CONNE_FA_TAX | M6: FA_TAX_EPMrestupload
A7: FTP_HCM_EPM_FILE_UPLOAD_01.00.0001.iar.yaml | B7: FTP_HCM_EPM_FILE_UPLOAD 01.00.0001 | C7: FTP_HCM_EPM_FILE_UPLOAD | D7: FTP HCM EPM File Upload | E7: 01.00.0001 | F7: ftp_location(i0) | G7: Adapter_Invoke | L7: ORCL-BRT-FTP_CONN | M7: ftp_location
A8: FTP_HCM_EPM_FILE_UPLOAD_01.00.0001.iar.yaml | B8: FTP_HCM_EPM_FILE_UPLOAD 01.00.0001 | C8: FTP_HCM_EPM_FILE_UPLOAD | D8: FTP HCM EPM File Upload | E8: 01.00.0001 | F8: epm_rest_upload(i1) | G8: Adapter_Invoke | K8: /interop/rest/11.1.2.3.600/applicationsnapshots/{file_name}/contents | L8: ORCL-BRT-REST-EPM_CONNECTION | M8: epm_rest_upload
A9: FTP_HCM_EPM_FILE_UPLOA_PROJE_01.00.0001.iar.yaml | B9: FTP_HCM_EPM_FILE_UPLOA_PROJE 01.00.0001 | C9: FTP_HCM_EPM_FILE_UPLOA_PROJE | D9: FTP HCM EPM File Upload_Projects | E9: 01.00.0001 | F9: ftp_location(i0) | G9: Adapter_Invoke | L9: ORCL-BRT-FTP_CONN | M9: ftp_location
A10: FTP_HCM_EPM_FILE_UPLOA_PROJE_01.00.0001.iar.yaml | B10: FTP_HCM_EPM_FILE_UPLOA_PROJE 01.00.0001 | C10: FTP_HCM_EPM_FILE_UPLOA_PROJE | D10: FTP HCM EPM File Upload_Projects | E10: 01.00.0001 | F10: epm_rest_upload(i1) | G10: Adapter_Invoke | K10: /interop/rest/11.1.2.3.600/applicationsnapshots/{file_name}/contents | L10: ORACLE_REST_EPM_CONNEC_PROJEC | M10: epm_rest_upload
A11: FTP_PPM_EPM_FILE_UPLOAD_01.00.0001.iar.yaml | B11: FTP_PPM_EPM_FILE_UPLOAD 01.00.0001 | C11: FTP_PPM_EPM_FILE_UPLOAD | D11: FTP PPM EPM File Upload | E11: 01.00.0001 | F11: ftp_location(i0) | G11: Adapter_Invoke | L11: ORCL-BRT-FTP_CONN | M11: ftp_location
A12: FTP_PPM_EPM_FILE_UPLOAD_01.00.0001.iar.yaml | B12: FTP_PPM_EPM_FILE_UPLOAD 01.00.0001 | C12: FTP_PPM_EPM_FILE_UPLOAD | D12: FTP PPM EPM File Upload | E12: 01.00.0001 | F12: epm_rest_upload(i1) | G12: Adapter_Invoke | K12: /interop/rest/11.1.2.3.600/applicationsnapshots/{file_name}/contents | L12: ORACLE_REST_EPM_CONNEC_PROJEC | M12: epm_rest_upload
A13: GET_SECRET_BY_NAME_01.00.0001.iar.yaml | B13: GET_SECRET_BY_NAME 01.00.0001 | C13: GET_SECRET_BY_NAME | D13: Get Secret By Name | E13: 01.00.0001 | F13: OCI_Secrete_By_Name(i0) | G13: Adapter_Invoke | K13: /20190301/secretbundles/actions/getByName | L13: OCI_VAULT_SECRETS | M13: OCI_Secrete_By_Name
A14: GET_SECRET_BY_NAME_01.00.0001.iar.yaml | B14: GET_SECRET_BY_NAME 01.00.0001 | C14: GET_SECRET_BY_NAME | D14: Get Secret By Name | E14: 01.00.0001 | F14: SendErrorNotification(i1) | G14: IntegrationAction | H14: SEND_EMAIL | I14: 01.00.0001 | J14: Send Email | K14: / | L14: PRESEEDED_COLLOCATED_CONN_1741 | M14: SendErrorNotification
A15: ORAC_UTIL_FPRC_WACS_VEND_LOC__CL_02.22.3001.iar.yaml | B15: ORAC_UTIL_FPRC_WACS_VEND_LOC__CL 02.22.3001 | C15: ORAC_UTIL_FPRC_WACS_VEND_LOC__CL | D15: Oracle Utilities FPRC WACS Vendor Loc -CLEANNER | E15: 02.22.3001 | F15: searchVendorLocationFile(i0) | G15: Adapter_Invoke | L15: OUTL-BRT-SOAP-UCM_WACSFPRC | M15: searchVendorLocationFile
A16: ORAC_UTIL_FPRC_WACS_VEND_LOC__CL_02.22.3001.iar.yaml | B16: ORAC_UTIL_FPRC_WACS_VEND_LOC__CL 02.22.3001 | C16: ORAC_UTIL_FPRC_WACS_VEND_LOC__CL | D16: Oracle Utilities FPRC WACS Vendor Loc -CLEANNER | E16: 02.22.3001 | F16: GetFileFromUCM(i2) | G16: Adapter_Invoke | L16: OUTL-BRT-SOAP-UCM_WACSFPRC | M16: GetFileFromUCM
A17: ORAC_UTIL_FPRC_WACS_VEND_LOC__CL_02.22.3001.iar.yaml | B17: ORAC_UTIL_FPRC_WACS_VEND_LOC__CL 02.22.3001 | C17: ORAC_UTIL_FPRC_WACS_VEND_LOC__CL | D17: Oracle Utilities FPRC WACS Vendor Loc -CLEANNER | E17: 02.22.3001 | F17: Rename_ZipFile_UnzipFault(i5) | G17: Adapter_Invoke | L17: OUTL-BRT-SOAP-UCM_WACSFPRC | M17: Rename_ZipFile_UnzipFault
A18: ORAC_UTIL_FPRC_WACS_VEND_LOC__CL_02.22.3001.iar.yaml | B18: ORAC_UTIL_FPRC_WACS_VEND_LOC__CL 02.22.3001 | C18: ORAC_UTIL_FPRC_WACS_VEND_LOC__CL | D18: Oracle Utilities FPRC WACS Vendor Loc -CLEANNER | E18: 02.22.3001 | F18: renameFileInUCM(i4) | G18: Adapter_Invoke | L18: OUTL-BRT-SOAP-UCM_WACSFPRC | M18: renameFileInUCM
A19: OUTL-BA-FPRC_WACS_BC_SYNC_01.22.3000.iar.yaml | B19: OUTL-BA-FPRC_WACS_BC_SYNC 01.22.3000 | C19: OUTL-BA-FPRC_WACS_BC_SYNC | D19: Oracle Utilities FPRC WACS Blanket Contracts Sync | E19: 01.22.3000 | F19: invokeWACS_HealthCheck(i0) | G19: Adapter_Invoke | K19: https://us-phoenix-1.utilities-cloud.oracleindustry.com:443/c2g65p/prod/wac/rest/apis/common/system/healthCheck/ | L19: OUTL-BRT-REST-WACS_WACSFPRC | M19: invokeWACS_HealthCheck
A20: OUTL-BA-FPRC_WACS_BC_SYNC_01.22.3000.iar.yaml | B20: OUTL-BA-FPRC_WACS_BC_SYNC 01.22.3000 | C20: OUTL-BA-FPRC_WACS_BC_SYNC | D20: Oracle Utilities FPRC WACS Blanket Contracts Sync | E20: 01.22.3000 | F20: searchBlanketContractFile(i1) | G20: Adapter_Invoke | L20: OUTL-BRT-SOAP-UCM_WACSFPRC | M20: searchBlanketContractFile
A21: OUTL-BA-FPRC_WACS_BC_SYNC_01.22.3000.iar.yaml | B21: OUTL-BA-FPRC_WACS_BC_SYNC 01.22.3000 | C21: OUTL-BA-FPRC_WACS_BC_SYNC | D21: Oracle Utilities FPRC WACS Blanket Contracts Sync | E21: 01.22.3000 | F21: GetFileFromUCM(i2) | G21: Adapter_Invoke | L21: OUTL-BRT-SOAP-UCM_WACSFPRC | M21: GetFileFromUCM
A22: OUTL-BA-FPRC_WACS_BC_SYNC_01.22.3000.iar.yaml | B22: OUTL-BA-FPRC_WACS_BC_SYNC 01.22.3000 | C22: OUTL-BA-FPRC_WACS_BC_SYNC | D22: Oracle Utilities FPRC WACS Blanket Contracts Sync | E22: 01.22.3000 | F22: invoke_UOMConversionRest(i5) | G22: Adapter_Invoke | L22: OUTL-BRT-ERPCLOUD_WACSFPRC | M22: invoke_UOMConversionRest
A23: OUTL-BA-FPRC_WACS_BC_SYNC_01.22.3000.iar.yaml | B23: OUTL-BA-FPRC_WACS_BC_SYNC 01.22.3000 | C23: OUTL-BA-FPRC_WACS_BC_SYNC | D23: Oracle Utilities FPRC WACS Blanket Contracts Sync | E23: 01.22.3000 | F23: InvokeWACSBCSync(i6) | G23: Adapter_Invoke | K23: https://us-phoenix-1.utilities-cloud.oracleindustry.com:443/c2g65p/prod/wac/rest/apis/asset/purchasing/blanketContractSynchronization/ | L23: OUTL-BRT-REST-WACS_WACSFPRC | M23: InvokeWACSBCSync
A24: OUTL-BA-FPRC_WACS_BC_SYNC_01.22.3000.iar.yaml | B24: OUTL-BA-FPRC_WACS_BC_SYNC 01.22.3000 | C24: OUTL-BA-FPRC_WACS_BC_SYNC | D24: Oracle Utilities FPRC WACS Blanket Contracts Sync | E24: 01.22.3000 | F24: remaneFileInUCM(i4) | G24: Adapter_Invoke | L24: OUTL-BRT-SOAP-UCM_WACSFPRC | M24: remaneFileInUCM
A25: OUTL-BA-FPRC_WACS_VEND_LOC_SYNC_01.22.3000.iar.yaml | B25: OUTL-BA-FPRC_WACS_VEND_LOC_SYNC 01.22.3000 | C25: OUTL-BA-FPRC_WACS_VEND_LOC_SYNC | D25: Oracle Utilities FPRC WACS Vendor Locations Sync | E25: 01.22.3000 | F25: invokeHealthCheck(i1) | G25: Adapter_Invoke | K25: https://us-phoenix-1.utilities-cloud.oracleindustry.com:443/c2g65p/prod/wac/rest/apis/common/system/healthCheck/ | L25: OUTL-BRT-REST-WACS_WACSFPRC | M25: invokeHealthCheck
A26: OUTL-BA-FPRC_WACS_VEND_LOC_SYNC_01.22.3000.iar.yaml | B26: OUTL-BA-FPRC_WACS_VEND_LOC_SYNC 01.22.3000 | C26: OUTL-BA-FPRC_WACS_VEND_LOC_SYNC | D26: Oracle Utilities FPRC WACS Vendor Locations Sync | E26: 01.22.3000 | F26: searchVendorLocationFile(i0) | G26: Adapter_Invoke | L26: OUTL-BRT-SOAP-UCM_WACSFPRC | M26: searchVendorLocationFile
A27: OUTL-BA-FPRC_WACS_VEND_LOC_SYNC_01.22.3000.iar.yaml | B27: OUTL-BA-FPRC_WACS_VEND_LOC_SYNC 01.22.3000 | C27: OUTL-BA-FPRC_WACS_VEND_LOC_SYNC | D27: Oracle Utilities FPRC WACS Vendor Locations Sync | E27: 01.22.3000 | F27: GetFileFromUCM(i2) | G27: Adapter_Invoke | L27: OUTL-BRT-SOAP-UCM_WACSFPRC | M27: GetFileFromUCM
A28: OUTL-BA-FPRC_WACS_VEND_LOC_SYNC_01.22.3000.iar.yaml | B28: OUTL-BA-FPRC_WACS_VEND_LOC_SYNC 01.22.3000 | C28: OUTL-BA-FPRC_WACS_VEND_LOC_SYNC | D28: Oracle Utilities FPRC WACS Vendor Locations Sync | E28: 01.22.3000 | F28: InvokeWACSVendorLocSync(i3) | G28: Adapter_Invoke | K28: https://us-phoenix-1.utilities-cloud.oracleindustry.com:443/c2g65p/prod/wac/rest/apis/asset/purchasing/vendorLocationSynchronization/ | L28: OUTL-BRT-REST-WACS_WACSFPRC | M28: InvokeWACSVendorLocSync
A29: OUTL-BA-FPRC_WACS_VEND_LOC_SYNC_01.22.3000.iar.yaml | B29: OUTL-BA-FPRC_WACS_VEND_LOC_SYNC 01.22.3000 | C29: OUTL-BA-FPRC_WACS_VEND_LOC_SYNC | D29: Oracle Utilities FPRC WACS Vendor Locations Sync | E29: 01.22.3000 | F29: renameFileInUCM(i4) | G29: Adapter_Invoke | L29: OUTL-BRT-SOAP-UCM_WACSFPRC | M29: renameFileInUCM
A30: OUTL-BA-OFSC_WACS_ACTIVITY_STAT_01.22.3000.iar.yaml | B30: OUTL-BA-OFSC_WACS_ACTIVITY_STAT 01.22.3000 | C30: OUTL-BA-OFSC_WACS_ACTIVITY_STAT | D30: Oracle Utilities OFSC WACS Activity Interim Status | E30: 01.22.3000 | F30: getActivityDetails(i1) | G30: Adapter_Invoke | K30: https://tsgt.fs.ocs.oraclecloud.com/rest/ofscCore/v1/activities/{activityId} | L30: OUTL-BRT-APP-OFSC_WACSOFSC | M30: getActivityDetails
A31: OUTL-BA-OFSC_WACS_ACTIVITY_STAT_01.22.3000.iar.yaml | B31: OUTL-BA-OFSC_WACS_ACTIVITY_STAT 01.22.3000 | C31: OUTL-BA-OFSC_WACS_ACTIVITY_STAT | D31: Oracle Utilities OFSC WACS Activity Interim Status | E31: 01.22.3000 | F31: UpdateInterimStatus(i0) | G31: Adapter_Invoke | L31: OUTL-BRT-SOAP-WACS_WACSOFSC | M31: UpdateInterimStatus
A32: OUTL-BA-OFSC_WACS_ASSET_QUERY_01.22.3000.iar.yaml | B32: OUTL-BA-OFSC_WACS_ASSET_QUERY 01.22.3000 | C32: OUTL-BA-OFSC_WACS_ASSET_QUERY | D32: Oracle Utilities OFSC WACS Asset Query | E32: 01.22.3000 | F32: AssetQuery(i0) | G32: Adapter_Invoke | L32: OUTL-BRT-SOAP-WACS_WACSOFSC | M32: AssetQuery
A33: OUTL-BA-OFSC_WACS_ASSET_QUERY_01.22.3000.iar.yaml | B33: OUTL-BA-OFSC_WACS_ASSET_QUERY 01.22.3000 | C33: OUTL-BA-OFSC_WACS_ASSET_QUERY | D33: Oracle Utilities OFSC WACS Asset Query | E33: 01.22.3000 | F33: MainAssetQueryForPickup(i1) | G33: Adapter_Invoke | L33: OUTL-BRT-SOAP-WACS_WACSOFSC | M33: MainAssetQueryForPickup
A34: OUTL-BA-OFSC_WACS_ASSET_QUERY_01.22.3000.iar.yaml | B34: OUTL-BA-OFSC_WACS_ASSET_QUERY 01.22.3000 | C34: OUTL-BA-OFSC_WACS_ASSET_QUERY | D34: Oracle Utilities OFSC WACS Asset Query | E34: 01.22.3000 | F34: GetAssetDetailsForPickup(i2) | G34: Adapter_Invoke | L34: OUTL-BRT-SOAP-WACS_WACSOFSC | M34: GetAssetDetailsForPickup
A35: OUTL-BA-OFSC_WACS_STOREROOM_SYNC_01.22.3000.iar.yaml | B35: OUTL-BA-OFSC_WACS_STOREROOM_SYNC 01.22.3000 | C35: OUTL-BA-OFSC_WACS_STOREROOM_SYNC | D35: Oracle Utilities OFSC WACS Storeroom Sync | E35: 01.22.3000 | F35: GetStoreroomInventoryFromWACS(i1) | G35: Adapter_Invoke | L35: OUTL-BRT-SOAP-WACS_WACSOFSC | M35: GetStoreroomInventoryFromWACS
A36: OUTL-BA-OFSC_WACS_STOREROOM_SYNC_01.22.3000.iar.yaml | B36: OUTL-BA-OFSC_WACS_STOREROOM_SYNC 01.22.3000 | C36: OUTL-BA-OFSC_WACS_STOREROOM_SYNC | D36: Oracle Utilities OFSC WACS Storeroom Sync | E36: 01.22.3000 | F36: resourceinventorybulk(i3) | G36: Adapter_Invoke | K36: /ofscCore/v1/resources/custom-actions/bulkUpdateInventories | L36: OUTL-BRT-REST-OFSC_WACSOFSC | M36: resourceinventorybulk
A37: OUTL-BA-OFSC_WACS_STOREROOM_SYNC_01.22.3000.iar.yaml | B37: OUTL-BA-OFSC_WACS_STOREROOM_SYNC 01.22.3000 | C37: OUTL-BA-OFSC_WACS_STOREROOM_SYNC | D37: Oracle Utilities OFSC WACS Storeroom Sync | E37: 01.22.3000 | F37: getResourceInventories(i4) | G37: Adapter_Invoke | K37: https://tsgt.fs.ocs.oraclecloud.com/rest/ofscCore/v1/resources/{resourceId}/inventories | L37: OUTL-BRT-APP-OFSC_WACSOFSC | M37: getResourceInventories
A38: OUTL-BA-OFSC_WACS_STOREROOM_SYNC_01.22.3000.iar.yaml | B38: OUTL-BA-OFSC_WACS_STOREROOM_SYNC 01.22.3000 | C38: OUTL-BA-OFSC_WACS_STOREROOM_SYNC | D38: Oracle Utilities OFSC WACS Storeroom Sync | E38: 01.22.3000 | F38: bulkupdateinventories(i5) | G38: Adapter_Invoke | K38: /ofscCore/v1/resources/custom-actions/bulkUpdateInventories | L38: OUTL-BRT-REST-OFSC_WACSOFSC | M38: bulkupdateinventories
A39: OUTL-BA-OFSC_WACS_STOREROOM_SYNC_01.22.3000.iar.yaml | B39: OUTL-BA-OFSC_WACS_STOREROOM_SYNC 01.22.3000 | C39: OUTL-BA-OFSC_WACS_STOREROOM_SYNC | D39: Oracle Utilities OFSC WACS Storeroom Sync | E39: 01.22.3000 | F39: UpdateResourceLastSyncDateTime(i0) | G39: Adapter_Invoke | K39: https://tsgt.fs.ocs.oraclecloud.com/rest/ofscCore/v1/resources/{resourceId} | L39: OUTL-BRT-APP-OFSC_WACSOFSC | M39: UpdateResourceLastSyncDateTime
A40: OUTL-BA-OFSC_WACS_WORK_REQ_01.22.3000.iar.yaml | B40: OUTL-BA-OFSC_WACS_WORK_REQ 01.22.3000 | C40: OUTL-BA-OFSC_WACS_WORK_REQ | D40: Oracle Utilities OFSC WACS Work Request | E40: 01.22.3000 | F40: createWorkRequest(i0) | G40: Adapter_Invoke | L40: OUTL-BRT-SOAP-WACS_WACSOFSC | M40: createWorkRequest
...
